<?xml version="1.0" ?>
<!-- =================================================================================== -->
<!-- |    This document was autogenerated by xacro from byrot_arm.urdf.xacro           | -->
<!-- |    EDITING THIS FILE BY HAND IS NOT RECOMMENDED                                 | -->
<!-- =================================================================================== -->
<robot name="robotic_arm">
  <!-- This file represents the description of a 5 DOF robotic arm -->
  <!-- Specify some colours -->
  <material name="blue">
    <color rgba="0 0 1 1"/>
  </material>
  <material name="red">
    <color rgba="1 0 0 1"/>
  </material>
  <material name="green">
    <color rgba="0 1 0 1"/>
  </material>
  <material name="black">
    <color rgba="0 0 0 1"/>
  </material>
  <material name="white">
    <color rgba="1 1 1 1"/>
  </material>
  <material name="orange">
    <color rgba="1 0.3 0.1 1"/>
  </material>
  <!-- Specify some standard inertial calculations https://en.wikipedia.org/wiki/List_of_moments_of_inertia -->
  <!-- These make use of xacro's mathematical functionality -->
  <link name="world"/>
  <joint name="world_base_joint" type="fixed">
    <origin rpy="0 0 0" xyz="1.5 0.0 0.0"/>
    <parent link="world"/>
    <child link="base_link"/>
  </joint>
  <link name="base_link">
    <visual>
      <geometry>
        <box size="0.2 0.15 0.075"/>
      </geometry>
      <origin xyz="0.0 0.0 0.0375"/>
      <material name="orange"/>
    </visual>
    <collision>
      <geometry>
        <box size="0.2 0.15 0.075"/>
      </geometry>
      <origin xyz="0.0 0.0 0.0375"/>
      <material name="orange"/>
    </collision>
    <inertial>
      <origin xyz="0 0 0.0375"/>
      <mass value="1"/>
      <inertia ixx="0.0023437499999999995" ixy="0.0" ixz="0.0" iyy="0.0038020833333333335" iyz="0.0" izz="0.005208333333333333"/>
    </inertial>
  </link>
  <joint name="base_waist_joint" type="revolute">
    <origin xyz="0.0 0.0 0.075"/>
    <parent link="base_link"/>
    <child link="waist_link"/>
    <axis xyz="0 0 1"/>
    <limit effort="100" lower="-3.141592" upper="3.141592" velocity="100"/>
  </joint>
  <link name="waist_link">
    <visual>
      <geometry>
        <box size="0.015 0.015 0.05"/>
      </geometry>
      <origin xyz="0.0 0.0 0.025"/>
      <material name="blue"/>
    </visual>
    <collision>
      <geometry>
        <box size="0.015 0.015 0.05"/>
      </geometry>
      <origin xyz="0.0 0.0 0.25"/>
      <material name="blue"/>
    </collision>
    <inertial>
      <origin xyz="0 0 0.25"/>
      <mass value="0.5"/>
      <inertia ixx="0.00011354166666666668" ixy="0.0" ixz="0.0" iyy="0.00011354166666666668" iyz="0.0" izz="1.875e-05"/>
    </inertial>
  </link>
  <joint name="waist_shoulder_joint" type="revolute">
    <origin xyz="0.0 0.0 0.05"/>
    <parent link="waist_link"/>
    <child link="shoulder_link"/>
    <axis xyz="0 -1 0"/>
    <limit effort="100" lower="-3.141592" upper="3.141592" velocity="100"/>
  </joint>
  <link name="shoulder_link">
    <visual>
      <geometry>
        <box size="0.01 0.01 0.1"/>
      </geometry>
      <origin xyz="0.0 0.0 0.05"/>
      <material name="blue"/>
    </visual>
    <collision>
      <geometry>
        <box size="0.01 0.01 0.1"/>
      </geometry>
      <origin xyz="0.0 0.0 0.05"/>
      <material name="blue"/>
    </collision>
    <inertial>
      <origin xyz="0 0 0.05"/>
      <mass value="0.2"/>
      <inertia ixx="0.00016833333333333335" ixy="0.0" ixz="0.0" iyy="0.00016833333333333335" iyz="0.0" izz="3.3333333333333333e-06"/>
    </inertial>
  </link>
  <joint name="shoulder_bicep_joint" type="revolute">
    <origin xyz="0.0 0.0 0.1"/>
    <parent link="shoulder_link"/>
    <child link="bicep_link"/>
    <axis xyz="0 -1 0"/>
    <limit effort="100" lower="-3.141592" upper="3.141592" velocity="100"/>
  </joint>
  <link name="bicep_link">
    <visual>
      <geometry>
        <box size="0.01 0.01 0.1"/>
      </geometry>
      <origin xyz="0.0 0.0 0.05"/>
      <material name="blue"/>
    </visual>
    <collision>
      <geometry>
        <box size="0.01 0.01 0.1"/>
      </geometry>
      <origin xyz="0.0 0.0 0.5"/>
      <material name="blue"/>
    </collision>
    <inertial>
      <origin xyz="0 0 0.05"/>
      <mass value="0.2"/>
      <inertia ixx="0.00016833333333333335" ixy="0.0" ixz="0.0" iyy="0.00016833333333333335" iyz="0.0" izz="3.3333333333333333e-06"/>
    </inertial>
  </link>
  <joint name="bicep_forearm_joint" type="revolute">
    <origin xyz="0.0 0.0 0.1"/>
    <parent link="bicep_link"/>
    <child link="forearm_link"/>
    <axis xyz="0 -1 0"/>
    <limit effort="100" lower="-3.141592" upper="3.141592" velocity="100"/>
  </joint>
  <link name="forearm_link">
    <visual>
      <geometry>
        <box size="0.01 0.01 0.1"/>
      </geometry>
      <origin xyz="0.0 0.0 0.05"/>
      <material name="blue"/>
    </visual>
    <collision>
      <geometry>
        <box size="0.01 0.01 0.1"/>
      </geometry>
      <origin xyz="0.0 0.0 0.05"/>
      <material name="blue"/>
    </collision>
    <inertial>
      <origin xyz="0 0 0.05"/>
      <mass value="0.2"/>
      <inertia ixx="0.00016833333333333335" ixy="0.0" ixz="0.0" iyy="0.00016833333333333335" iyz="0.0" izz="3.3333333333333333e-06"/>
    </inertial>
  </link>
  <joint name="forearm_hand_joint" type="revolute">
    <origin xyz="0.0 0.0 0.1"/>
    <parent link="forearm_link"/>
    <child link="hand_link"/>
    <axis xyz="0 0 1"/>
    <limit effort="100" lower="-3.141592" upper="3.141592" velocity="100"/>
  </joint>
  <link name="hand_link" type="fixed">
    <visual>
      <geometry>
        <box size="0.03 0.01 0.01"/>
      </geometry>
      <origin xyz="0.0 0.0 0.005"/>
      <material name="green"/>
    </visual>
    <collision>
      <geometry>
        <box size="0.03 0.01 0.01"/>
      </geometry>
      <origin xyz="0.0 0.0 0.005"/>
      <material name="green"/>
    </collision>
    <inertial>
      <origin xyz="0 0 0.005"/>
      <mass value="0.02"/>
      <inertia ixx="3.3333333333333335e-07" ixy="0.0" ixz="0.0" iyy="1.6666666666666667e-06" iyz="0.0" izz="1.6666666666666667e-06"/>
    </inertial>
  </link>
  <joint name="hand_finger1_joint" type="prismatic">
    <origin xyz="0.01125 0.0 0.01"/>
    <parent link="hand_link"/>
    <child link="finger1_link"/>
    <axis xyz="-1 0 0"/>
    <limit effort="100" lower="0" upper="0.0075" velocity="100"/>
  </joint>
  <link name="finger1_link">
    <visual>
      <geometry>
        <box size="0.0075 0.01 0.02"/>
      </geometry>
      <origin xyz="0.0 0.0 0.01"/>
      <material name="green"/>
    </visual>
    <collision>
      <geometry>
        <box size="0.0075 0.01 0.02"/>
      </geometry>
      <origin xyz="0.0 0.0 0.01"/>
      <material name="green"/>
    </collision>
    <inertial>
      <origin xyz="0 0 0.01"/>
      <mass value="0.02"/>
      <inertia ixx="8.333333333333333e-07" ixy="0.0" ixz="0.0" iyy="7.604166666666667e-07" iyz="0.0" izz="2.604166666666667e-07"/>
    </inertial>
  </link>
  <joint name="hand_finger2_joint" type="prismatic">
    <origin xyz="-0.01125 0.0 0.01"/>
    <parent link="hand_link"/>
    <child link="finger2_link"/>
    <axis xyz="1 0 0"/>
    <limit effort="100" lower="0" upper="0.0075" velocity="100"/>
  </joint>
  <link name="finger2_link">
    <visual>
      <geometry>
        <box size="0.0075 0.01 0.02"/>
      </geometry>
      <origin xyz="0.0 0.0 0.01"/>
      <material name="green"/>
    </visual>
    <collision>
      <geometry>
        <box size="0.0075 0.01 0.02"/>
      </geometry>
      <origin xyz="0.0 0.0 0.01"/>
      <material name="green"/>
    </collision>
    <inertial>
      <origin xyz="0 0 0.01"/>
      <mass value="0.02"/>
      <inertia ixx="8.333333333333333e-07" ixy="0.0" ixz="0.0" iyy="7.604166666666667e-07" iyz="0.0" izz="2.604166666666667e-07"/>
    </inertial>
  </link>
</robot>
